<sdf version='1.6'>
  <model name='pioneer'>
    <link name='base_link'>
      <pose frame=''>0 0 0 0 -0 0</pose>
      <inertial>
        <pose frame=''>-0.082207 0 0.130515 0 -0 0</pose>
        <mass>20.3202</mass>
        <inertia>
          <ixx>7.34232</ixx>
          <ixy>0</ixy>
          <ixz>-0.00893517</ixz>
          <iyy>7.49717</iyy>
          <iyz>0</iyz>
          <izz>7.34415</izz>
        </inertia>
      </inertial>
      <collision name='base_link_fixed_joint_lump__robot_collision_collision'>
        <pose frame=''>-0.045 0 0.148 0 -0 0</pose>
        <geometry>
          <box>
            <size>0.42 0.28 0.17</size>
          </box>
        </geometry>
      </collision>
      <collision name='base_link_fixed_joint_lump__hokuyo_front_link_collision_1'>
        <pose frame=''>0.13 0 0.25 0 -0 0</pose>
        <geometry>
          <box>
            <size>0.05 0.05 0.075</size>
          </box>
        </geometry>
        <surface>
          <contact>
            <ode/>
          </contact>
          <friction>
            <ode/>
          </friction>
        </surface>
      </collision>
      <collision name='base_link_fixed_joint_lump__kinect_stand_link_collision_2'>
        <pose frame=''>0.06 0 0.2725 0 -0 0</pose>
        <geometry>
          <cylinder>
            <length>0.065</length>
            <radius>0.02</radius>
          </cylinder>
        </geometry>
        <surface>
          <contact>
            <ode/>
          </contact>
          <friction>
            <ode/>
          </friction>
        </surface>
      </collision>
      <collision name='base_link_fixed_joint_lump__kinect_camera_link_collision_3'>
        <pose frame=''>0.067419 0 0.330279 0 0.2 0</pose>
        <geometry>
          <box>
            <size>0.073 0.276 0.072</size>
          </box>
        </geometry>
        <surface>
          <contact>
            <ode/>
          </contact>
          <friction>
            <ode/>
          </friction>
        </surface>
      </collision>
      <visual name='base_link_visual'>
        <pose frame=''>-0.045 0 0.148 0 -0 0</pose>
        <geometry>
          <mesh>
            <scale>1 1 1</scale>
            <uri>file:///home/csrobot/catkin_ws/src/uml_hri_nerve_nav_sim_resources/resources/models/pioneer/meshes/chassis.stl</uri>
          </mesh>
        </geometry>
        <material>
          <script>
            <name>Gazebo/Red</name>
            <uri>file://media/materials/scripts/gazebo.material</uri>
          </script>
        </material>
      </visual>
      <visual name='base_link_fixed_joint_lump__back_sonar_visual_1'>
        <pose frame=''>0.109 0 0.209 0 -0 0</pose>
        <geometry>
          <mesh>
            <scale>1 1 1</scale>
            <uri>file:///home/csrobot/catkin_ws/src/uml_hri_nerve_nav_sim_resources/resources/models/pioneer/meshes/back_sonar.stl</uri>
          </mesh>
        </geometry>
        <material>
          <script>
            <name>Gazebo/Yellow</name>
            <uri>file://media/materials/scripts/gazebo.material</uri>
          </script>
        </material>
      </visual>
      <visual name='base_link_fixed_joint_lump__hokuyo_front_link_visual_2'>
        <pose frame=''>0.13 0 0.25 0 -0 0</pose>
        <geometry>
          <mesh>
            <scale>1 1 1</scale>
            <uri>file:///home/csrobot/catkin_ws/src/uml_hri_nerve_nav_sim_resources/resources/models/pioneer/meshes/hokuyo.dae</uri>
          </mesh>
        </geometry>
        <material>
          <script>
            <uri>__default__</uri>
            <name>__default__</name>
          </script>
        </material>
      </visual>
      <visual name='base_link_fixed_joint_lump__front_sonar_visual_3'>
        <pose frame=''>-0.198 0 0.208 0 -0 0</pose>
        <geometry>
          <mesh>
            <scale>1 1 1</scale>
            <uri>file:///home/csrobot/catkin_ws/src/uml_hri_nerve_nav_sim_resources/resources/models/pioneer/meshes/front_sonar.stl</uri>
          </mesh>
        </geometry>
        <material>
          <script>
            <name>Gazebo/Yellow</name>
            <uri>file://media/materials/scripts/gazebo.material</uri>
          </script>
        </material>
      </visual>
      <visual name='base_link_fixed_joint_lump__kinect_stand_link_visual_4'>
        <pose frame=''>0.06 0 0.2725 0 -0 0</pose>
        <geometry>
          <cylinder>
            <length>0.065</length>
            <radius>0.02</radius>
          </cylinder>
        </geometry>
        <material>
          <script>
            <name>Gazebo/Red</name>
            <uri>file://media/materials/scripts/gazebo.material</uri>
          </script>
        </material>
      </visual>
      <visual name='base_link_fixed_joint_lump__kinect_camera_link_visual_5'>
        <pose frame=''>0.1 0 0.34 0 0.2 0</pose>
        <geometry>
          <mesh>
            <scale>1 1 1</scale>
            <uri>file:///home/csrobot/catkin_ws/src/uml_hri_nerve_nav_sim_resources/resources/models/pioneer/meshes/kinect.dae</uri>
          </mesh>
        </geometry>
        <material>
          <script>
            <uri>__default__</uri>
            <name>__default__</name>
          </script>
        </material>
      </visual>
      <visual name='base_link_fixed_joint_lump__top_plate_visual_6'>
        <pose frame=''>-0.045 0 0.24 0 -0 0</pose>
        <geometry>
          <mesh>
            <scale>1 1 1</scale>
            <uri>file:///home/csrobot/catkin_ws/src/uml_hri_nerve_nav_sim_resources/resources/models/pioneer/meshes/top.stl</uri>
          </mesh>
        </geometry>
        <material>
          <script>
            <name>Gazebo/Black</name>
            <uri>file://media/materials/scripts/gazebo.material</uri>
          </script>
        </material>
      </visual>
      <velocity_decay/>
      <velocity_decay/>
      <velocity_decay/>
      <sensor name='frontlaser' type='ray'>
        <ray>
          <scan>
            <horizontal>
              <samples>240</samples>
              <resolution>1</resolution>
              <min_angle>-2.26889</min_angle>
              <max_angle>2.26889</max_angle>
            </horizontal>
            <vertical>
              <samples>1</samples>
              <min_angle>0</min_angle>
              <max_angle>0</max_angle>
            </vertical>
          </scan>
          <range>
            <min>0.08</min>
            <max>10</max>
            <resolution>0.01</resolution>
          </range>
        </ray>
        <plugin name='frontlaser' filename='libgazebo_ros_laser.so'>
          <topicName>pioneer/frontscan</topicName>
          <frameName>pioneer/hokuyo_front_link</frameName>
        </plugin>
        <always_on>1</always_on>
        <update_rate>30</update_rate>
        <visualize>1</visualize>
        <pose frame=''>0.13 0 0.275 0 -0 0</pose>
      </sensor>
      <velocity_decay/>
      <velocity_decay/>
      <velocity_decay/>
      <sensor name='kinect_camera' type='depth'>
        <update_rate>20</update_rate>
        <camera name='__default__'>
          <horizontal_fov>1.0472</horizontal_fov>
          <image>
            <width>640</width>
            <height>480</height>
            <format>R8G8B8</format>
          </image>
          <clip>
            <near>0.05</near>
            <far>5</far>
          </clip>
        </camera>
        <plugin name='kinect_camera_plugin' filename='libgazebo_ros_openni_kinect.so'>
          <baseline>0.2</baseline>
          <alwaysOn>true</alwaysOn>
          <updateRate>20.0</updateRate>
          <cameraName>kinect</cameraName>
          <imageTopicName>/kinect/rgb/image_raw</imageTopicName>
          <cameraInfoTopicName>/kinect/depth/camera_info</cameraInfoTopicName>
          <depthImageTopicName>/kinect/depth/image_raw</depthImageTopicName>
          <depthImageInfoTopicName>/kinect/depth/camera_info</depthImageInfoTopicName>
          <pointCloudTopicName>/kinect/depth/points</pointCloudTopicName>
          <frameName>pioneer/kinect_sensor_link</frameName>
          <pointCloudCutoff>0.05</pointCloudCutoff>
          <distortionK1>0</distortionK1>
          <distortionK2>0</distortionK2>
          <distortionK3>0</distortionK3>
          <distortionT1>0</distortionT1>
          <distortionT2>0</distortionT2>
          <CxPrime>0</CxPrime>
          <Cx>0</Cx>
          <Cy>0</Cy>
          <focalLength>0</focalLength>
          <hackBaseline>0</hackBaseline>
        </plugin>
        <always_on>1</always_on>
        <visualize>1</visualize>
        <pose frame=''>0.1 0 0.34 0 0.2 0</pose>
      </sensor>
      <gravity>1</gravity>
      <velocity_decay/>
      <self_collide>0</self_collide>
    </link>
    <link name='p3dx_left_wheel'>
      <pose frame=''>0 0.158 0.091 0 -0 0</pose>
      <inertial>
        <pose frame=''>0 0 0 0 -0 0</pose>
        <mass>0.51</mass>
        <inertia>
          <ixx>0.0248235</ixx>
          <ixy>0</ixy>
          <ixz>0</ixz>
          <iyy>0.0304363</iyy>
          <iyz>0</iyz>
          <izz>0.023528</izz>
        </inertia>
      </inertial>
      <collision name='p3dx_left_wheel_collision'>
        <pose frame=''>0 0 0 -1.5708 0 0</pose>
        <geometry>
          <cylinder>
            <length>0.04</length>
            <radius>0.09</radius>
          </cylinder>
        </geometry>
        <surface>
          <contact>
            <ode>
              <kp>1e+08</kp>
              <kd>1</kd>
            </ode>
          </contact>
          <friction>
            <ode>
              <mu>0.5</mu>
              <mu2>50</mu2>
            </ode>
          </friction>
        </surface>
      </collision>
      <visual name='p3dx_left_wheel_visual'>
        <pose frame=''>0 0 0 0 -0 0</pose>
        <geometry>
          <mesh>
            <scale>1 1 1</scale>
            <uri>file:///home/csrobot/catkin_ws/src/uml_hri_nerve_nav_sim_resources/resources/models/pioneer/meshes/left_wheel.stl</uri>
          </mesh>
        </geometry>
        <material>
          <script>
            <name>Gazebo/Black</name>
            <uri>file://media/materials/scripts/gazebo.material</uri>
          </script>
        </material>
      </visual>
      <visual name='p3dx_left_wheel_fixed_joint_lump__p3dx_left_hubcap_visual_1'>
        <pose frame=''>0 0 0 0 -0 0</pose>
        <geometry>
          <mesh>
            <scale>1 1 1</scale>
            <uri>file:///home/csrobot/catkin_ws/src/uml_hri_nerve_nav_sim_resources/resources/models/pioneer/meshes/left_hubcap.stl</uri>
          </mesh>
        </geometry>
        <material>
          <script>
            <name>Gazebo/Yellow</name>
            <uri>file://media/materials/scripts/gazebo.material</uri>
          </script>
        </material>
      </visual>
      <velocity_decay/>
      <gravity>1</gravity>
      <velocity_decay/>
      <self_collide>0</self_collide>
    </link>
    <joint name='base_left_wheel_joint' type='revolute'>
      <child>p3dx_left_wheel</child>
      <parent>base_link</parent>
      <axis>
        <xyz>0 1 0</xyz>
        <limit>
          <lower>-1e+16</lower>
          <upper>1e+16</upper>
        </limit>
        <dynamics>
          <spring_reference>0</spring_reference>
          <spring_stiffness>0</spring_stiffness>
        </dynamics>
        <use_parent_model_frame>1</use_parent_model_frame>
      </axis>
    </joint>
    <link name='p3dx_right_wheel'>
      <pose frame=''>0 -0.158 0.091 0 -0 0</pose>
      <inertial>
        <pose frame=''>0 0 0 0 -0 0</pose>
        <mass>0.51</mass>
        <inertia>
          <ixx>0.0248235</ixx>
          <ixy>0</ixy>
          <ixz>0</ixz>
          <iyy>0.0304363</iyy>
          <iyz>0</iyz>
          <izz>0.023528</izz>
        </inertia>
      </inertial>
      <collision name='p3dx_right_wheel_collision'>
        <pose frame=''>0 0 0 -1.5708 0 0</pose>
        <geometry>
          <cylinder>
            <length>0.04</length>
            <radius>0.09</radius>
          </cylinder>
        </geometry>
        <surface>
          <contact>
            <ode>
              <kp>1e+08</kp>
              <kd>1</kd>
            </ode>
          </contact>
          <friction>
            <ode>
              <mu>0.5</mu>
              <mu2>50</mu2>
            </ode>
          </friction>
        </surface>
      </collision>
      <visual name='p3dx_right_wheel_visual'>
        <pose frame=''>0 0 0 0 -0 0</pose>
        <geometry>
          <mesh>
            <scale>1 1 1</scale>
            <uri>file:///home/csrobot/catkin_ws/src/uml_hri_nerve_nav_sim_resources/resources/models/pioneer/meshes/right_wheel.stl</uri>
          </mesh>
        </geometry>
        <material>
          <script>
            <name>Gazebo/Black</name>
            <uri>file://media/materials/scripts/gazebo.material</uri>
          </script>
        </material>
      </visual>
      <visual name='p3dx_right_wheel_fixed_joint_lump__p3dx_right_hubcap_visual_1'>
        <pose frame=''>0 0 0 0 -0 0</pose>
        <geometry>
          <mesh>
            <scale>1 1 1</scale>
            <uri>file:///home/csrobot/catkin_ws/src/uml_hri_nerve_nav_sim_resources/resources/models/pioneer/meshes/right_hubcap.stl</uri>
          </mesh>
        </geometry>
        <material>
          <script>
            <name>Gazebo/Yellow</name>
            <uri>file://media/materials/scripts/gazebo.material</uri>
          </script>
        </material>
      </visual>
      <velocity_decay/>
      <gravity>1</gravity>
      <velocity_decay/>
      <self_collide>0</self_collide>
    </link>
    <joint name='base_right_wheel_joint' type='revolute'>
      <child>p3dx_right_wheel</child>
      <parent>base_link</parent>
      <axis>
        <xyz>0 1 0</xyz>
        <limit>
          <lower>-1e+16</lower>
          <upper>1e+16</upper>
        </limit>
        <dynamics>
          <spring_reference>0</spring_reference>
          <spring_stiffness>0</spring_stiffness>
        </dynamics>
        <use_parent_model_frame>1</use_parent_model_frame>
      </axis>
    </joint>
    <link name='swivel_link'>
      <pose frame=''>-0.185 0 0.055 0 -0 0</pose>
      <inertial>
        <pose frame=''>0 0 0 0 -0 0</pose>
        <mass>0.1</mass>
        <inertia>
          <ixx>0.01</ixx>
          <ixy>0</ixy>
          <ixz>0</ixz>
          <iyy>0.01</iyy>
          <iyz>0</iyz>
          <izz>0.01</izz>
        </inertia>
      </inertial>
      <visual name='swivel_link_visual'>
        <pose frame=''>0 0 0 0 -0 0</pose>
        <geometry>
          <mesh>
            <scale>1 1 1</scale>
            <uri>file:///home/csrobot/catkin_ws/src/uml_hri_nerve_nav_sim_resources/resources/models/pioneer/meshes/swivel.stl</uri>
          </mesh>
        </geometry>
        <material>
          <script>
            <name>Gazebo/Black</name>
            <uri>file://media/materials/scripts/gazebo.material</uri>
          </script>
        </material>
      </visual>
      <gravity>1</gravity>
      <velocity_decay/>
      <self_collide>0</self_collide>
    </link>
    <joint name='base_swivel_joint' type='revolute'>
      <child>swivel_link</child>
      <parent>base_link</parent>
      <axis>
        <xyz>0 0 1</xyz>
        <limit>
          <lower>-1e+16</lower>
          <upper>1e+16</upper>
        </limit>
        <dynamics>
          <spring_reference>0</spring_reference>
          <spring_stiffness>0</spring_stiffness>
        </dynamics>
        <use_parent_model_frame>1</use_parent_model_frame>
      </axis>
    </joint>
    <link name='center_wheel'>
      <pose frame=''>-0.211 0 0.039 0 -0 0</pose>
      <inertial>
        <pose frame=''>-0.000318 0 -9.1e-05 0 -0 0</pose>
        <mass>0.11</mass>
        <inertia>
          <ixx>0.0248235</ixx>
          <ixy>-0.00142347</ixy>
          <ixz>0.00100543</ixz>
          <iyy>0.0304364</iyy>
          <iyz>-8.54693e-06</iyz>
          <izz>0.0235281</izz>
        </inertia>
      </inertial>
      <collision name='center_wheel_collision'>
        <pose frame=''>0 0 0 -1.5708 0 0</pose>
        <geometry>
          <cylinder>
            <length>0.0314</length>
            <radius>0.0375</radius>
          </cylinder>
        </geometry>
        <surface>
          <contact>
            <ode/>
          </contact>
          <friction>
            <ode/>
          </friction>
        </surface>
      </collision>
      <visual name='center_wheel_visual'>
        <pose frame=''>0 0 0 0 -0 0</pose>
        <geometry>
          <mesh>
            <scale>1 1 1</scale>
            <uri>file:///home/csrobot/catkin_ws/src/uml_hri_nerve_nav_sim_resources/resources/models/pioneer/meshes/center_wheel.stl</uri>
          </mesh>
        </geometry>
        <material>
          <script>
            <name>Gazebo/Black</name>
            <uri>file://media/materials/scripts/gazebo.material</uri>
          </script>
        </material>
      </visual>
      <visual name='center_wheel_fixed_joint_lump__center_hubcap_visual_1'>
        <pose frame=''>-0.0035 0 -0.001 0 -0 0</pose>
        <geometry>
          <mesh>
            <scale>1 1 1</scale>
            <uri>file:///home/csrobot/catkin_ws/src/uml_hri_nerve_nav_sim_resources/resources/models/pioneer/meshes/center_hubcap.stl</uri>
          </mesh>
        </geometry>
        <material>
          <script>
            <name>Gazebo/Black</name>
            <uri>file://media/materials/scripts/gazebo.material</uri>
          </script>
        </material>
      </visual>
      <velocity_decay/>
      <gravity>1</gravity>
      <velocity_decay/>
      <self_collide>0</self_collide>
    </link>
    <joint name='swivel_hubcap_joint' type='revolute'>
      <child>center_wheel</child>
      <parent>swivel_link</parent>
      <axis>
        <xyz>0 1 0</xyz>
        <limit>
          <lower>-1e+16</lower>
          <upper>1e+16</upper>
        </limit>
        <dynamics>
          <spring_reference>0</spring_reference>
          <spring_stiffness>0</spring_stiffness>
        </dynamics>
        <use_parent_model_frame>1</use_parent_model_frame>
      </axis>
    </joint>
    <static>0</static>
    <plugin name='differential_drive_controller' filename='libgazebo_ros_diff_drive.so'>
      <legacyMode>false</legacyMode>
      <alwaysOn>true</alwaysOn>
      <updateRate>100.0</updateRate>
      <leftJoint>base_left_wheel_joint</leftJoint>
      <rightJoint>base_right_wheel_joint</rightJoint>
      <wheelSeparation>0.32</wheelSeparation>
      <wheelDiameter>0.18</wheelDiameter>
      <wheelTorque>5</wheelTorque>
      <wheelAcceleration>0</wheelAcceleration>
      <robotNamespace>pioneer</robotNamespace>
      <commandTopic>cmd_vel</commandTopic>
      <odometryTopic>odom</odometryTopic>
      <odometryFrame>odom</odometryFrame>
      <robotBaseFrame>base_link</robotBaseFrame>
      <publishTf>1</publishTf>
      <publishWheelTF>true</publishWheelTF>
      <publishOdomTF>true</publishOdomTF>
      <publishWheelJointState>true</publishWheelJointState>
      <rosDebugLevel>Warn</rosDebugLevel>
    </plugin>
    <plugin name='ground_truth_odometry' filename='libgazebo_ros_p3d.so'>
      <alwaysOn>true</alwaysOn>
      <updateRate>100.0</updateRate>
      <bodyName>base_link</bodyName>
      <topicName>base_pose_ground_truth</topicName>
      <gaussianNoise>0.01</gaussianNoise>
      <frameName>map</frameName>
      <xyzOffsets>0 0 0</xyzOffsets>
      <rpyOffsets>0 0 0</rpyOffsets>
    </plugin>
  </model>
</sdf>
